input.txt
ABC buy limit 1000 24.50 Giant Hedge Fund

ABC buy limit 500 24.75 Namini Fund

ABC sell market 80 0 BU Investment Fund

ABC buy limit 800 24.90 Quantlab

ABC sell limit 600 25.00 Questrom Fund

ABC buy limit 700 24.58 ITG

ABC sell market 100 0 Tim Fund

ABC buy market 600 0 Ruolei Fund

ABC buy market 100 0 Carl Fund

ABC sell market 300 0 JP Morgan

ABC buy limit 400 24.85 Goldman Sachs

ABC buy limit 300 24.87 Morgan Stanley

ABC sell limit 400 25.90 Ryan Fund

ABC buy limit 100 25.11 Luo Asset Management

ABC buy market 500 0 Ruolei Fund

ABC sell limit 500 25.90 Ryan Fund

ABC sell limit 10 25.90 Will Fund

ABC buy limit 95 24.75 Terry Fund 

ABC sell limit 360 25.53 ITG

ABC buy market 400 0 Questrom Fund


ABC buy limit 200 25 Izzy Fund
